<?xml version="1.0" ?>

<robot xmlns:xacro="http://www.ros.org/wiki/xacro" name="foxbot2">
  <xacro:property name="wheelMass" value="0.2" />
  <xacro:property name="wheelLength" value="0.04" />
  <xacro:property name="wheelRadius" value="0.1" />

  <xacro:macro name="colour" params="link colourName">
    <gazebo reference="link_${link}">
      <material>Gazebo/${colourName}</material>
    </gazebo>
  </xacro:macro>
  
  <xacro:colour link="chassis" colourName="Orange"/>
  <xacro:colour link="left_front_wheel" colourName="Black"/>
  <xacro:colour link="right_front_wheel" colourName="Black"/>
  <xacro:colour link="left_back_wheel" colourName="Black"/>
  <xacro:colour link="right_back_wheel" colourName="Black"/>
  
  <xacro:macro name="wheel" params="linkName posX posY">
    <link name="link_${linkName}">    
      <inertial>
        <mass value="${wheelMass}"/>
        <origin rpy="0 1.5707 1.5707" xyz="0 0 0"/>
        <inertia ixx="0.00052666666" ixy="0" ixz="0" iyy="0.00052666666" iyz="0" izz="0.001"/>
      </inertial>
      
      <collision name="link_${linkName}_collision">
        <origin rpy="0 1.5707 1.5707" xyz="0 0 0" />
        <geometry>
      <cylinder length="${wheelLength}" radius="${wheelRadius}"/>
        </geometry>
      </collision>

      <visual name="link_${linkName}_visual">
        <origin rpy="0 1.5707 1.5707" xyz="0 0 0"/>
        <geometry>
      <cylinder length="${wheelLength}" radius="${wheelRadius}"/>
        </geometry>      
      </visual>    
    </link>

    <!--   Joint for wheel  -->
    <joint name="joint_${linkName}" type="continuous">
      <origin rpy="0 0 0" xyz="${posX} ${posY} 0"/>
      <child link="link_${linkName}" />
      <parent link="link_chassis"/>
      <axis rpy="0 0 0" xyz="0 1 0"/>
      <limit effort="10000" velocity="1000"/>
      <joint_properties damping="1.0" friction="1.0" />
    </joint> 

    <transmission name="trans_${linkName}">
      <type>transmission_interface/SimpleTransmission</type>
      <joint name="joint_${linkName}">
        <hardwareInterface>hardware_interface/VelocityJointInterface</hardwareInterface>
      </joint>
      <actuator name="${linkName}_motor">
        <hardwareInterface>hardware_interface/VelocityJointInterface</hardwareInterface>
        <mechanicalReduction>1</mechanicalReduction>
      </actuator>
    </transmission>

  </xacro:macro>
    
  <link name="link_chassis">
    <!-- pose and inertial -->
    <pose>0 0 0 0 0 0</pose>
    
    <inertial>
      <mass value="5"/>
      <origin rpy="0 0 0" xyz="0 0 0"/>
      <inertia ixx="0.0395416666667" ixy="0" ixz="0" iyy="0.106208333333" iyz="0" izz="0.106208333333"/>
    </inertial>
    
    <collision name="collision_chassis">
      <geometry>
    <box size="0.5 0.3 0.07"/>
      </geometry>
    </collision>
    
    <visual>
      <origin rpy="0 0 0" xyz="0 0 0"/>
      <geometry>
    <box size="0.5 0.3 0.07"/>
      </geometry>
      <material name="blue"/>
    </visual>
  </link>
  
  <!-- Create right wheel -->  
  <xacro:wheel linkName="right_back_wheel" posX="-0.2" posY="0.2"/>
  <!-- Create left wheel  --> 
  <xacro:wheel linkName="left_back_wheel" posX="-0.2" posY="-0.2"/>

  <!-- Create right wheel -->  
  <xacro:wheel linkName="right_front_wheel" posX="0.2" posY="0.2"/>
  <!-- Create left wheel  --> 
  <xacro:wheel linkName="left_front_wheel" posX="0.2" posY="-0.2"/>      
  

  <gazebo>
    <plugin name="gazebo_ros_control" filename="libgazebo_ros_control.so">
      <robotNamespace>/foxbot2</robotNamespace>
      <legacyModeNS>true</legacyModeNS>
    </plugin>
  </gazebo>

  <joint name="ir_front_joint" type="fixed">
    <axis xyz="0 1 0" />
    <origin rpy="0 0 0" xyz="0.3 0 0" />
    <parent link="link_chassis"/>
    <child link="base_ir_front"/>
  </joint>
  <link name="base_ir_front">
    <collision>
      <origin xyz="0 0 0" rpy="0 0 0"/>
      <geometry>
        <box size="0.01 0.01 0.01"/>
      </geometry>
    </collision>
    <visual>
      <origin xyz="0 0 0" rpy="0 0 0"/>
      <geometry>
        <box size="0.01 0.01 0.01"/>
      </geometry>
    </visual>
    <inertial>
      <mass value="1e-5" />
      <origin xyz="0 0 0" rpy="0 0 0"/>
      <inertia ixx="1e-6" ixy="0" ixz="0" iyy="1e-6" iyz="0"      izz="1e-6" />
    </inertial>
  </link>

  <gazebo reference="base_ir_front">        
   <sensor type="ray" name="TeraRanger">
      <pose>0 0 0 0 0 0</pose>
      <visualize>true</visualize>
      <update_rate>50</update_rate>
      <ray>
         <scan>
            <horizontal>
               <samples>10</samples>
               <resolution>1</resolution> 
               <min_angle>-0.1</min_angle>
               <max_angle>0.1</max_angle>
            </horizontal>
            <vertical>
               <samples>10</samples>
               <resolution>1</resolution> 
               <min_angle>-0</min_angle>
               <max_angle>0</max_angle> 
            </vertical>
         </scan>
         <range>
            <min>0.01</min>
            <max>5</max>
            <resolution>0.02</resolution>
         </range>
      </ray>
      <plugin filename="libgazebo_ros_range.so" name="gazebo_ros_range">
         <gaussianNoise>0.005</gaussianNoise>
         <alwaysOn>true</alwaysOn>
         <updateRate>50</updateRate>
         <topicName>sensor/ir_front</topicName>
         <frameName>base_ir_front</frameName>
         <radiation>INFRARED</radiation>
         <fov>0.2967</fov>
      </plugin>
   </sensor>  
   </gazebo>

  <!-- <transmission name="trans_1">
      <type>transmission_interface/SimpleTransmission</type>
      <joint name="joint_right_back_wheel">
        <hardwareInterface>hardware_interface/EffortJointInterface</hardwareInterface>
      </joint>
      <actuator name="right_back_wheel_motor">
        <hardwareInterface>hardware_interface/EffortJointInterface</hardwareInterface>
        <mechanicalReduction>1</mechanicalReduction>
      </actuator>
  </transmission>
  <transmission name="trans_2">
      <type>transmission_interface/SimpleTransmission</type>
      <joint name="joint_left_back_wheel">
        <hardwareInterface>hardware_interface/EffortJointInterface</hardwareInterface>
      </joint>
      <actuator name="left_back_wheel_motor">
        <hardwareInterface>hardware_interface/EffortJointInterface</hardwareInterface>
        <mechanicalReduction>1</mechanicalReduction>
      </actuator>
  </transmission>
  <transmission name="trans_3">
      <type>transmission_interface/SimpleTransmission</type>
      <joint name="joint_right_front_wheel">
        <hardwareInterface>hardware_interface/EffortJointInterface</hardwareInterface>
      </joint>
      <actuator name="right_front_wheel_motor">
        <hardwareInterface>hardware_interface/EffortJointInterface</hardwareInterface>
        <mechanicalReduction>1</mechanicalReduction>
      </actuator>
  </transmission>
  <transmission name="trans_4">
      <type>transmission_interface/SimpleTransmission</type>
      <joint name="joint_left_front_wheel">
        <hardwareInterface>hardware_interface/EffortJointInterface</hardwareInterface>
      </joint>
      <actuator name="left_front_wheel_motor">
        <hardwareInterface>hardware_interface/EffortJointInterface</hardwareInterface>
        <mechanicalReduction>1</mechanicalReduction>
      </actuator>
  </transmission> -->
</robot>